INFO 2023-12-01 15:09:08,061 Watching for file changes with StatReloader
WARNING 2023-12-01 15:09:10,448 Not Found: /
WARNING 2023-12-01 15:09:10,449 "GET / HTTP/1.1" 404 2495
INFO 2023-12-01 15:11:56,178 C:\Users\feron\Kurss_D\django_d4\simpleapp\urls.py changed, reloading.
INFO 2023-12-01 15:11:57,407 Watching for file changes with StatReloader
WARNING 2023-12-01 15:12:03,744 Not Found: /news/
WARNING 2023-12-01 15:12:03,745 "GET /news/ HTTP/1.1" 404 2528
WARNING 2023-12-01 15:12:12,725 Not Found: /ndexleng
WARNING 2023-12-01 15:12:12,726 "GET /ndexleng HTTP/1.1" 404 2537
WARNING 2023-12-01 15:14:04,231 Not Found: /ndexleng
WARNING 2023-12-01 15:14:04,232 "GET /ndexleng HTTP/1.1" 404 2537
INFO 2023-12-01 15:14:04,317 C:\Users\feron\Kurss_D\django_d4\simpleapp\views.py changed, reloading.
INFO 2023-12-01 15:14:06,133 Watching for file changes with StatReloader
WARNING 2023-12-01 15:14:49,699 Not Found: /indexleng
WARNING 2023-12-01 15:14:49,701 "GET /indexleng HTTP/1.1" 404 2540
WARNING 2023-12-01 15:15:26,348 Not Found: /indexleng
WARNING 2023-12-01 15:15:26,350 "GET /indexleng HTTP/1.1" 404 2540
WARNING 2023-12-01 15:15:41,592 Not Found: /index
WARNING 2023-12-01 15:15:41,593 "GET /index HTTP/1.1" 404 2528
WARNING 2023-12-01 15:16:17,949 Not Found: /pages/index
WARNING 2023-12-01 15:16:17,950 "GET /pages/index HTTP/1.1" 404 2509
WARNING 2023-12-01 15:16:38,919 Not Found: /index
WARNING 2023-12-01 15:16:38,920 "GET /index HTTP/1.1" 404 2528
INFO 2023-12-01 15:17:04,304 "GET /products/index HTTP/1.1" 301 0
WARNING 2023-12-01 15:17:24,130 Not Found: /
WARNING 2023-12-01 15:17:24,131 "GET / HTTP/1.1" 404 2495
INFO 2023-12-01 15:17:38,189 "GET /multiply/ HTTP/1.1" 200 49
WARNING 2023-12-01 15:18:14,228 Not Found: /multiply/indexleng/
WARNING 2023-12-01 15:18:14,230 "GET /multiply/indexleng/ HTTP/1.1" 404 2570
ERROR 2023-12-01 15:18:53,802 Internal Server Error: /products/index/
Traceback (most recent call last):
  File "C:\Users\feron\Kurss_D\django_d4\venv\lib\site-packages\redis\connection.py", line 707, in connect
    sock = self.retry.call_with_retry(
  File "C:\Users\feron\Kurss_D\django_d4\venv\lib\site-packages\redis\retry.py", line 46, in call_with_retry
    return do()
  File "C:\Users\feron\Kurss_D\django_d4\venv\lib\site-packages\redis\connection.py", line 708, in <lambda>
    lambda: self._connect(), lambda error: self.disconnect(error)
  File "C:\Users\feron\Kurss_D\django_d4\venv\lib\site-packages\redis\connection.py", line 1006, in _connect
    raise err
  File "C:\Users\feron\Kurss_D\django_d4\venv\lib\site-packages\redis\connection.py", line 994, in _connect
    sock.connect(socket_address)
ConnectionRefusedError: [WinError 10061] Подключение не установлено, т.к. конечный компьютер отверг запрос на подключение

During handling of the above exception, another exception occurred:

Traceback (most recent call last):
  File "C:\Users\feron\Kurss_D\django_d4\venv\lib\site-packages\celery\backends\redis.py", line 127, in reconnect_on_error
    yield
  File "C:\Users\feron\Kurss_D\django_d4\venv\lib\site-packages\celery\backends\redis.py", line 177, in _consume_from
    self._pubsub.subscribe(key)
  File "C:\Users\feron\Kurss_D\django_d4\venv\lib\site-packages\redis\client.py", line 1634, in subscribe
    ret_val = self.execute_command("SUBSCRIBE", *new_channels.keys())
  File "C:\Users\feron\Kurss_D\django_d4\venv\lib\site-packages\redis\client.py", line 1469, in execute_command
    self.connection = self.connection_pool.get_connection(
  File "C:\Users\feron\Kurss_D\django_d4\venv\lib\site-packages\redis\connection.py", line 1461, in get_connection
    connection.connect()
  File "C:\Users\feron\Kurss_D\django_d4\venv\lib\site-packages\redis\connection.py", line 713, in connect
    raise ConnectionError(self._error_message(e))
redis.exceptions.ConnectionError: Error 10061 connecting to localhost:6379. Подключение не установлено, т.к. конечный компьютер отверг запрос на подключение.

During handling of the above exception, another exception occurred:

Traceback (most recent call last):
  File "C:\Users\feron\Kurss_D\django_d4\venv\lib\site-packages\redis\connection.py", line 707, in connect
    sock = self.retry.call_with_retry(
  File "C:\Users\feron\Kurss_D\django_d4\venv\lib\site-packages\redis\retry.py", line 46, in call_with_retry
    return do()
  File "C:\Users\feron\Kurss_D\django_d4\venv\lib\site-packages\redis\connection.py", line 708, in <lambda>
    lambda: self._connect(), lambda error: self.disconnect(error)
  File "C:\Users\feron\Kurss_D\django_d4\venv\lib\site-packages\redis\connection.py", line 1006, in _connect
    raise err
  File "C:\Users\feron\Kurss_D\django_d4\venv\lib\site-packages\redis\connection.py", line 994, in _connect
    sock.connect(socket_address)
ConnectionRefusedError: [WinError 10061] Подключение не установлено, т.к. конечный компьютер отверг запрос на подключение

During handling of the above exception, another exception occurred:

Traceback (most recent call last):
  File "C:\Users\feron\Kurss_D\django_d4\venv\lib\site-packages\kombu\connection.py", line 472, in _reraise_as_library_errors
    yield
  File "C:\Users\feron\Kurss_D\django_d4\venv\lib\site-packages\celery\app\base.py", line 797, in send_task
    self.backend.on_task_call(P, task_id)
  File "C:\Users\feron\Kurss_D\django_d4\venv\lib\site-packages\celery\backends\redis.py", line 373, in on_task_call
    self.result_consumer.consume_from(task_id)
  File "C:\Users\feron\Kurss_D\django_d4\venv\lib\site-packages\celery\backends\redis.py", line 169, in consume_from
    return self.start(task_id)
  File "C:\Users\feron\Kurss_D\django_d4\venv\lib\site-packages\celery\backends\redis.py", line 147, in start
    self._consume_from(initial_task_id)
  File "C:\Users\feron\Kurss_D\django_d4\venv\lib\site-packages\celery\backends\redis.py", line 176, in _consume_from
    with self.reconnect_on_error():
  File "C:\Users\feron\AppData\Local\Programs\Python\Python310\lib\contextlib.py", line 153, in __exit__
    self.gen.throw(typ, value, traceback)
  File "C:\Users\feron\Kurss_D\django_d4\venv\lib\site-packages\celery\backends\redis.py", line 130, in reconnect_on_error
    self._ensure(self._reconnect_pubsub, ())
  File "C:\Users\feron\Kurss_D\django_d4\venv\lib\site-packages\celery\backends\redis.py", line 384, in ensure
    return retry_over_time(
  File "C:\Users\feron\Kurss_D\django_d4\venv\lib\site-packages\kombu\utils\functional.py", line 318, in retry_over_time
    return fun(*args, **kwargs)
  File "C:\Users\feron\Kurss_D\django_d4\venv\lib\site-packages\celery\backends\redis.py", line 106, in _reconnect_pubsub
    metas = self.backend.client.mget(self.subscribed_to)
  File "C:\Users\feron\Kurss_D\django_d4\venv\lib\site-packages\redis\commands\core.py", line 2002, in mget
    return self.execute_command("MGET", *args, **options)
  File "C:\Users\feron\Kurss_D\django_d4\venv\lib\site-packages\redis\client.py", line 1266, in execute_command
    conn = self.connection or pool.get_connection(command_name, **options)
  File "C:\Users\feron\Kurss_D\django_d4\venv\lib\site-packages\redis\connection.py", line 1461, in get_connection
    connection.connect()
  File "C:\Users\feron\Kurss_D\django_d4\venv\lib\site-packages\redis\connection.py", line 713, in connect
    raise ConnectionError(self._error_message(e))
redis.exceptions.ConnectionError: Error 10061 connecting to localhost:6379. Подключение не установлено, т.к. конечный компьютер отверг запрос на подключение.

The above exception was the direct cause of the following exception:

Traceback (most recent call last):
  File "C:\Users\feron\Kurss_D\django_d4\venv\lib\site-packages\django\core\handlers\exception.py", line 55, in inner
    response = get_response(request)
  File "C:\Users\feron\Kurss_D\django_d4\venv\lib\site-packages\django\core\handlers\base.py", line 197, in _get_response
    response = wrapped_callback(request, *callback_args, **callback_kwargs)
  File "C:\Users\feron\Kurss_D\django_d4\venv\lib\site-packages\django\views\generic\base.py", line 104, in view
    return self.dispatch(request, *args, **kwargs)
  File "C:\Users\feron\Kurss_D\django_d4\venv\lib\site-packages\django\views\generic\base.py", line 143, in dispatch
    return handler(request, *args, **kwargs)
  File "C:\Users\feron\Kurss_D\django_d4\simpleapp\views.py", line 233, in get
    hello.delay()
  File "C:\Users\feron\Kurss_D\django_d4\venv\lib\site-packages\celery\app\task.py", line 444, in delay
    return self.apply_async(args, kwargs)
  File "C:\Users\feron\Kurss_D\django_d4\venv\lib\site-packages\celery\app\task.py", line 594, in apply_async
    return app.send_task(
  File "C:\Users\feron\Kurss_D\django_d4\venv\lib\site-packages\celery\app\base.py", line 795, in send_task
    with P.connection._reraise_as_library_errors():
  File "C:\Users\feron\AppData\Local\Programs\Python\Python310\lib\contextlib.py", line 153, in __exit__
    self.gen.throw(typ, value, traceback)
  File "C:\Users\feron\Kurss_D\django_d4\venv\lib\site-packages\kombu\connection.py", line 476, in _reraise_as_library_errors
    raise ConnectionError(str(exc)) from exc
kombu.exceptions.OperationalError: Error 10061 connecting to localhost:6379. Подключение не установлено, т.к. конечный компьютер отверг запрос на подключение.
ERROR 2023-12-01 15:18:55,370 "GET /products/index/ HTTP/1.1" 500 267407
INFO 2023-12-01 15:18:57,047 "GET /products/ HTTP/1.1" 200 6538
INFO 2023-12-01 15:21:05,220 C:\Users\feron\Kurss_D\django_d4\simpleapp\views.py changed, reloading.
INFO 2023-12-01 15:21:06,821 Watching for file changes with StatReloader
WARNING 2023-12-01 15:21:14,060 Not Found: /
WARNING 2023-12-01 15:21:14,065 "GET / HTTP/1.1" 404 2495
WARNING 2023-12-01 15:21:38,226 Not Found: /indexleng
WARNING 2023-12-01 15:21:38,228 "GET /indexleng HTTP/1.1" 404 2540
INFO 2023-12-01 15:24:18,609 C:\Users\feron\Kurss_D\django_d4\django_d4\urls.py changed, reloading.
INFO 2023-12-01 15:24:19,828 Watching for file changes with StatReloader
WARNING 2023-12-01 15:24:22,114 Not Found: /
WARNING 2023-12-01 15:24:22,124 "GET / HTTP/1.1" 404 2605
INFO 2023-12-01 15:24:38,703 "GET /indexleng HTTP/1.1" 301 0
INFO 2023-12-01 15:24:38,710 "GET /indexleng/ HTTP/1.1" 200 14
INFO 2023-12-01 15:24:58,237 C:\Users\feron\Kurss_D\django_d4\simpleapp\urls.py changed, reloading.
INFO 2023-12-01 15:24:59,577 Watching for file changes with StatReloader
INFO 2023-12-01 15:25:02,223 C:\Users\feron\Kurss_D\django_d4\simpleapp\urls.py changed, reloading.
INFO 2023-12-01 15:25:04,730 Watching for file changes with StatReloader
INFO 2023-12-01 15:25:48,859 "GET /indexleng/ HTTP/1.1" 200 14
WARNING 2023-12-01 15:26:27,866 Not Found: /favicon.ico
WARNING 2023-12-01 15:26:27,867 "GET /favicon.ico HTTP/1.1" 404 2656
INFO 2023-12-01 15:28:06,628 C:\Users\feron\Kurss_D\django_d4\django_d4\settings.py changed, reloading.
